<?xml version="1.0" ?>
<sdf version="1.5">
  <model name="omo_r1">
        <!-- Init colour -->
    <material name="black">
        <color rgba="0.0 0.0 0.0 1.0"/>
    </material>

    <material name="dark">
      <color rgba="0.3 0.3 0.3 1.0"/>
    </material>

    <material name="light_black">
      <color rgba="0.4 0.4 0.4 1.0"/>
    </material>

    <material name="blue">
      <color rgba="0.0 0.0 0.8 1.0"/>
    </material>

    <material name="green">
      <color rgba="0.0 0.8 0.0 1.0"/>
    </material>

    <material name="grey">
      <color rgba="0.5 0.5 0.5 1.0"/>
    </material>

    <material name="orange">
      <color rgba="1.0 0.4235 0.0392 1.0"/>
    </material>

    <material name="brown">
      <color rgba="0.8706 0.8118 0.7647 1.0"/>
    </material>

    <material name="red">
      <color rgba="0.8 0.0 0.0 1.0"/>
    </material>

    <material name="white">
      <color rgba="1.0 1.0 1.0 1.0"/>
    </material>

    <pose>0.0 0.0 0.02 0.0 0.0 0.0</pose>

    <link name="base_footprint"/>

    <joint name="base_joint" type="fixed">
      <parent>base_footprint</parent>
      <child>base_link</child>
      <pose>0 0 0.07 0 0 0</pose>
    </joint>

    <link name="base_link">
      <inertial>
        <pose>-0.028 0 0 0 0 0</pose>
        <inertia>
          <ixx>2.2124416e-02</ixx>
          <ixy>-1.2294101e-04</ixy>
          <ixz>3.4938785e-04</ixz>
          <iyy>2.1193702e-02</iyy>
          <iyz>-5.0120904e-05</iyz>
          <izz>2.0064271e-02</izz>
        </inertia>
        <mass>8.2573504</mass>
      </inertial>
      <collision name="base_link_collision">
        <pose>0.097 0.276 0.19 3.14 0 -1.57</pose>
        <geometry>
          <mesh>
            <uri>model://omo_r1/meshes/bases/omo_r1_body.stl</uri>
            <scale>0.001 0.001 0.001</scale>
          </mesh>
        </geometry>
      </collision>
      <visual name="base_link_visual">
        <pose>0.097 0.276 0.19 3.14 0 -1.57</pose>
        <geometry>
          <mesh>
            <uri>model://omo_r1/meshes/bases/omo_r1_body.stl</uri>
            <scale>0.001 0.001 0.001</scale>
          </mesh>
        </geometry>
      </visual>
    </link>
 
    <joint name="wheel_left_joint" type="revolute">
      <parent>base_link</parent>
      <child>wheel_left_link</child>
      <pose>0 0.275 0.037 0 0 0</pose>
      <axis>
        <xyz>0 1 0</xyz>
      </axis>
    </joint>

    <link name="wheel_left_link">
      <inertial>
        <pose>0 0 0 0 0 0</pose>
        <inertia>
          <ixx>1.1175580e-03</ixx>
          <ixy>-4.2369783e-08</ixy>
          <ixz>-5.9381719e-07</ixz>
          <iyy>1.1192413e-03</iyy>
          <iyz>-1.4400107e-08</iyz>
          <izz>2.0712558e-03</izz>
        </inertia>
        <mass>2.8498940</mass>
      </inertial>
      <collision name="wheel_left_collision">
        <pose>-0.1105 -0.06 0.1104 -1.57 0 0</pose>
        <geometry>
          <mesh>
            <uri>model://omo_r1/meshes/wheels/omo_r1_wheel.stl</uri>
            <scale>0.001 0.001 0.001</scale>
          </mesh>
        </geometry>
        <surface>
          <friction>
            <ode>
              <mu>100000.0</mu>
              <mu2>100000.0</mu2>
              <fdir1>1 1 0</fdir1>
              <slip1>0.0</slip1>
              <slip2>0.0</slip2>
            </ode>
          </friction>
          <contact>
            <ode>
              <soft_cfm>0</soft_cfm>
              <soft_erp>0.2</soft_erp>
              <kp>100000</kp>
              <kd>1</kd>
              <max_vel>0.5</max_vel>
              <min_depth>0.001</min_depth>
            </ode>
          </contact>
        </surface>
      </collision>
      <visual name="wheel_left_visual">
        <pose>-0.1105 -0.06 0.01104 -1.57 0 0</pose>
        <geometry>
          <mesh>
            <uri>model://omo_r1/meshes/wheels/omo_r1_wheel.stl</uri>
            <scale>0.001 0.001 0.001</scale>
          </mesh>
        </geometry>
        <material name="dark"/>
      </visual>
    </link>

    <joint name="wheel_right_joint" type="revolute">
      <parent>base_link</parent>
      <child>wheel_right_link</child>
      <pose>0.0 -0.275 0.037 0.0 0 0</pose>
      <axis>
        <xyz>0 1 0</xyz>
      </axis>
    </joint>

    <link name="wheel_right_link">
      <inertial>
        <pose>0 0 0 0 0 0</pose>
        <inertia>
          <ixx>1.1175580e-03</ixx>
          <ixy>-4.2369783e-08</ixy>
          <ixz>-5.9381719e-07</ixz>
          <iyy>1.1192413e-03</iyy>
          <iyz>-1.4400107e-08</iyz>
          <izz>2.0712558e-03</izz>
        </inertia>
        <mass>2.8498940</mass>
      </inertial>
      <collision name="wheel_right_collision">
        <pose>-0.110 -0.06 0.1103 1.57 0 0</pose>
        <geometry>
          <mesh>
            <uri>model://omo_r1/meshes/wheels/omo_r1_wheel.stl</uri>
            <scale>0.001 0.001 0.001</scale>
          </mesh>
        </geometry>
        <surface>
          <friction>
            <ode>
              <mu>100000.0</mu>
              <mu2>100000.0</mu2>
              <fdir1>1 1 0</fdir1>
              <slip1>0.0</slip1>
              <slip2>0.0</slip2>
            </ode>
          </friction>
          <contact>
            <ode>
              <soft_cfm>0</soft_cfm>
              <soft_erp>0.2</soft_erp>
              <kp>100000</kp>
              <kd>1</kd>
              <max_vel>0.5</max_vel>
              <min_depth>0.001</min_depth>
            </ode>
          </contact>
        </surface>
      </collision>
      <visual name="wheel_right_visual">
        <pose>-0.110 0.06 -0.1103 1.57 0 0</pose>
        <geometry>
          <mesh>
            <uri>model://omo_r1/meshes/wheels/omo_r1_wheel.stl</uri>
            <scale>0.001 0.001 0.001</scale>
          </mesh>
        </geometry>
      </visual>
    </link>

    <joint name="caster_back_right_joint" type="fixed">
      <parent>base_link</parent>
      <child>caster_back_right_link</child>
      <pose>-0.33 -0.148 -0.06 0 0 0</pose>
    </joint>

    <link name="caster_back_right_link">
      <inertial>
        <pose>0.0 0.0 0.0 0 0 0</pose>
        <inertia>
          <ixx>0.000001</ixx>
          <ixy>0.000000</ixy>
          <ixz>0.000000</ixz>
          <iyy>0.000001</iyy>
          <iyz>0.000000</iyz>
          <izz>0.000001</izz>
        </inertia>
        <mass>0.1</mass>
      </inertial>
      <collision name="caster_back_right_link_collision">
        <pose>-0.33 -0.148 -0.06 0 0 0</pose>
        <geometry>
          <box> 
            <size>0.01 0.01 0.01"</size>
          </box>
        </geometry>
      </collision>
      <visual name="caster_back_right_link_visual">
        <pose>-0.10375 0.0 -0.00180 0 0 0</pose>
        <geometry>
          <box> 
            <size>0.01 0.01 0.01"</size>
          </box>
        </geometry>
      </visual>
    </link>

    <joint name="caster_back_left_joint" type="fixed">
      <parent>base_link</parent>
      <child>caster_back_left_link</child>
      <pose>-0.33 0.148 -0.06 0 0 0</pose>
    </joint>

    <link name="caster_back_left_link">
      <inertial>
        <pose>0.0 0.0 0.0 0 0 0</pose>
        <inertia>
          <ixx>0.000001</ixx>
          <ixy>0.000000</ixy>
          <ixz>0.000000</ixz>
          <iyy>0.000001</iyy>
          <iyz>0.000000</iyz>
          <izz>0.000001</izz>
        </inertia>
        <mass>0.1</mass>
      </inertial>
      <collision name="caster_back_left_link_collision">
        <pose>0 0.000 -0.133 0 0 0</pose>
        <geometry>
          <box> 
            <size>0.01 0.01 0.01"</size>
          </box>
        </geometry>
      </collision>
      <visual name="caster_back_left_link_visual">
        <pose>-0.10375 0.0 -0.00180 0 0 0</pose>
        <geometry>
          <box> 
            <size>0.01 0.01 0.01"</size>
          </box>
        </geometry>
      </visual>
    </link>

    <joint name="imu_joint" type="fixed">
      <parent>base_link</parent>
      <child>imu_link</child>
      <pose>0.0 0.0 0.168 0 0 0</pose>
      <axis>
        <xyz>0 0 1</xyz>
      </axis>
    </joint>

    <link name="imu_link">
      <sensor name="omo_r1_imu" type="imu">
        <always_on>true</always_on>
        <update_rate>200</update_rate>
        <imu>
          <angular_velocity>
            <x>
              <noise type="gaussian">
                <mean>0.0</mean>
                <stddev>2e-4</stddev>
              </noise>
            </x>
            <y>
              <noise type="gaussian">
                <mean>0.0</mean>
                <stddev>2e-4</stddev>
              </noise>
            </y>
            <z>
              <noise type="gaussian">
                <mean>0.0</mean>
                <stddev>2e-4</stddev>
              </noise>
            </z>
          </angular_velocity>
          <linear_acceleration>
            <x>
              <noise type="gaussian">
                <mean>0.0</mean>
                <stddev>1.7e-2</stddev>
              </noise>
            </x>
            <y>
              <noise type="gaussian">
                <mean>0.0</mean>
                <stddev>1.7e-2</stddev>
              </noise>
            </y>
            <z>
              <noise type="gaussian">
                <mean>0.0</mean>
                <stddev>1.7e-2</stddev>
              </noise>
            </z>
          </linear_acceleration>
        </imu>
        <plugin name="omo_r1_imu" filename="libgazebo_ros_imu_sensor.so">
          <ros>
            <remapping>~/out:=imu</remapping>
          </ros>
        </plugin>
      </sensor>
    </link>

    <joint name="scan_joint" type="fixed">
      <parent>base_link</parent>
      <child>base_scan</child>
      <pose>0.08 0 0.180 0 0 0</pose>
      <axis>
        <xyz>0 0 1</xyz>
      </axis>
    </joint>

    <link name="base_scan">
      <inertial>
        <pose>0.114 0 0 0 0 0</pose>
        <inertia>
          <ixx>0.001</ixx>
          <ixy>0.000000</ixy>
          <ixz>0.000000</ixz>
          <iyy>0.001</iyy>
          <iyz>0.000000</iyz>
          <izz>0.001</izz>
        </inertia>
        <mass>0.114</mass>
      </inertial>

      <collision name="lidar_sensor_collision">
        <pose>0 0 0 0 0 0</pose>
        <geometry>
          <mesh>
            <uri>model://omo_r1/meshes/sensors/ydlidar_assy.dae</uri>
            <scale>1 1 1</scale>
          </mesh>
        </geometry>
      </collision>

      <visual name="lidar_sensor_visual">
        <pose>0 0 0 0 0 0</pose>
        <geometry>
          <mesh>
            <uri>model://omo_r1/meshes/sensors/ydlidar_assy.dae</uri>
            <scale>1 1 1</scale>
          </mesh>
        </geometry>
      </visual>

      <sensor name="ydlidar" type="ray">
        <always_on>true</always_on>
        <visualize>true</visualize>
        <pose>0 0 0.081 0 0 0</pose>
        <update_rate>5</update_rate>
        <ray>
          <scan>
            <horizontal>
              <samples>360</samples>
              <resolution>1.000000</resolution>
              <min_angle>0.000000</min_angle>
              <max_angle>6.280000</max_angle>
            </horizontal>
          </scan>
          <range>
            <min>0.120000</min>
            <max>3.0</max>
            <resolution>0.015000</resolution>
          </range>
          <noise>
            <type>gaussian</type>
            <mean>0.0</mean>
            <stddev>0.01</stddev>
          </noise>
        </ray>
        <plugin name="omo_r1_laserscan" filename="libgazebo_ros_ray_sensor.so">
          <ros>
            <remapping>~/out:=scan</remapping>
          </ros>
          <output_type>sensor_msgs/LaserScan</output_type>
          <frame_name>base_scan</frame_name>
        </plugin>
      </sensor>
    </link>

    <plugin name="omo_r1_diff_drive" filename="libgazebo_ros_diff_drive.so">
      <update_rate>30</update_rate>

      <left_joint>wheel_left_joint</left_joint>
      <right_joint>wheel_right_joint</right_joint>

      <wheel_separation>0.650</wheel_separation>
      <wheel_diameter>0.22</wheel_diameter>

      <max_wheel_torque>100</max_wheel_torque>
      <max_wheel_acceleration>1.0</max_wheel_acceleration>

      <command_topic>cmd_vel</command_topic>

      <publish_odom>true</publish_odom>
      <publish_odom_tf>true</publish_odom_tf>
      <publish_wheel_tf>false</publish_wheel_tf>

      <odometry_topic>odom</odometry_topic>
      <odometry_frame>odom</odometry_frame>
      <robot_base_frame>base_footprint</robot_base_frame>

    </plugin>

    <plugin name="omo_r1_joint_state" filename="libgazebo_ros_joint_state_publisher.so">
      <ros>
        <remapping>~/out:=joint_states</remapping>
      </ros>
      <update_rate>30</update_rate>
      <joint_name>wheel_left_joint</joint_name>
      <joint_name>wheel_right_joint</joint_name>
    </plugin>

  </model>
</sdf>
